<?xml version="1.0" encoding="utf-8"?>
<!-- This URDF was automatically created by SolidWorks to URDF Exporter! Originally created by Stephen Brawner (brawner@gmail.com) 
     Commit Version: 1.6.0-4-g7f85cfe  Build Version: 1.6.7995.38578
     For more information, please see http://wiki.ros.org/sw_urdf_exporter -->
<robot
  name="conn_t2_newcoord">
  <link
    name="arm_base">
    <inertial>
      <origin
        xyz="0.45322 0.033083 0.78329"
        rpy="0 0 0" />
      <mass
        value="0.286" />
      <inertia
        ixx="0.00019821"
        ixy="1.0823E-08"
        ixz="8.0776E-10"
        iyy="0.00019354"
        iyz="3.7082E-09"
        izz="0.00025727" />
    </inertial>
    <visual>
      <origin
        xyz="0 0 0"
        rpy="0 0 0" />
      <geometry>
        <mesh
          filename="package://conn_t2_newcoord/meshes/arm_base.STL" />
      </geometry>
      <material
        name="">
        <color
          rgba="0.79216 0.81961 0.93333 1" />
      </material>
    </visual>
    <collision>
      <origin
        xyz="0 0 0"
        rpy="0 0 0" />
      <geometry>
        <mesh
          filename="package://conn_t2_newcoord/meshes/arm_base.STL" />
      </geometry>
    </collision>
  </link>
  <link
    name="arm_link1">
    <inertial>
      <origin
        xyz="-1.1102E-16 -1.1102E-16 0.037783"
        rpy="0 0 0" />
      <mass
        value="0.094869" />
      <inertia
        ixx="2.4878E-05"
        ixy="1.7322E-19"
        ixz="6.309E-21"
        iyy="6.4515E-05"
        iyz="1.2078E-20"
        izz="4.9982E-05" />
    </inertial>
    <visual>
      <origin
        xyz="0 0 0"
        rpy="0 0 0" />
      <geometry>
        <mesh
          filename="package://conn_t2_newcoord/meshes/arm_link1.STL" />
      </geometry>
      <material
        name="">
        <color
          rgba="0.79216 0.81961 0.93333 1" />
      </material>
    </visual>
    <collision>
      <origin
        xyz="0 0 0"
        rpy="0 0 0" />
      <geometry>
        <mesh
          filename="package://conn_t2_newcoord/meshes/arm_link1.STL" />
      </geometry>
    </collision>
  </link>
  <joint
    name="arm_joint1"
    type="revolute">
    <origin
      xyz="0.4628 -0.78323 0.076176"
      rpy="0 0 -1.8902" />
    <parent
      link="arm_base" />
    <child
      link="arm_link1" />
    <axis
      xyz="0 0 -1" />
    <limit
      lower="-1.57"
      upper="1.57"
      effort="300"
      velocity="3" />
  </joint>
  <link
    name="arm_link2">
    <inertial>
      <origin
        xyz="-0.00029354 -1.1344E-06 0.13543"
        rpy="0 0 0" />
      <mass
        value="0.21279" />
      <inertia
        ixx="0.0009982"
        ixy="2.6616E-12"
        ixz="2.8954E-06"
        iyy="0.00098076"
        iyz="1.8483E-11"
        izz="4.0091E-05" />
    </inertial>
    <visual>
      <origin
        xyz="0 0 0"
        rpy="0 0 0" />
      <geometry>
        <mesh
          filename="package://conn_t2_newcoord/meshes/arm_link2.STL" />
      </geometry>
      <material
        name="">
        <color
          rgba="0.79216 0.81961 0.93333 1" />
      </material>
    </visual>
    <collision>
      <origin
        xyz="0 0 0"
        rpy="0 0 0" />
      <geometry>
        <mesh
          filename="package://conn_t2_newcoord/meshes/arm_link2.STL" />
      </geometry>
    </collision>
  </link>
  <joint
    name="arm_joint2"
    type="revolute">
    <origin
      xyz="0 0 0.054102"
      rpy="0 1.0219 -1.5708" />
    <parent
      link="arm_link1" />
    <child
      link="arm_link2" />
    <axis
      xyz="0 -1 0" />
    <limit
      lower="-1"
      upper="1"
      effort="200"
      velocity="3" />
  </joint>
  <link
    name="arm_link3">
    <inertial>
      <origin
        xyz="0.11206 -1.1272E-05 -0.00021438"
        rpy="0 0 0" />
      <mass
        value="0.1797" />
      <inertia
        ixx="2.2862E-05"
        ixy="-7.3792E-08"
        ixz="-2.8502E-08"
        iyy="0.00081885"
        iyz="1.2022E-08"
        izz="0.00082384" />
    </inertial>
    <visual>
      <origin
        xyz="0 0 0"
        rpy="0 0 0" />
      <geometry>
        <mesh
          filename="package://conn_t2_newcoord/meshes/arm_link3.STL" />
      </geometry>
      <material
        name="">
        <color
          rgba="0.79216 0.81961 0.93333 1" />
      </material>
    </visual>
    <collision>
      <origin
        xyz="0 0 0"
        rpy="0 0 0" />
      <geometry>
        <mesh
          filename="package://conn_t2_newcoord/meshes/arm_link3.STL" />
      </geometry>
    </collision>
  </link>
  <joint
    name="arm_joint3"
    type="revolute">
    <origin
      xyz="-0.03 0 0.25884"
      rpy="-1.5708 0.85285 -3.1416" />
    <parent
      link="arm_link2" />
    <child
      link="arm_link3" />
    <axis
      xyz="0 0 -1" />
    <limit
      lower="-1"
      upper="1"
      effort="200"
      velocity="3" />
  </joint>
  <link
    name="arm_link4">
    <inertial>
      <origin
        xyz="-0.028886 -0.00048525 0.00096005"
        rpy="0 0 0" />
      <mass
        value="0.003657" />
      <inertia
        ixx="1.1514E-06"
        ixy="-1.3799E-12"
        ixz="1.3125E-07"
        iyy="1.4718E-06"
        iyz="7.9322E-13"
        izz="2.3304E-06" />
    </inertial>
    <visual>
      <origin
        xyz="0 0 0"
        rpy="0 0 0" />
      <geometry>
        <mesh
          filename="package://conn_t2_newcoord/meshes/arm_link4.STL" />
      </geometry>
      <material
        name="">
        <color
          rgba="0.79216 0.81961 0.93333 1" />
      </material>
    </visual>
    <collision>
      <origin
        xyz="0 0 0"
        rpy="0 0 0" />
      <geometry>
        <mesh
          filename="package://conn_t2_newcoord/meshes/arm_link4.STL" />
      </geometry>
    </collision>
  </link>
  <joint
    name="arm_joint4"
    type="revolute">
    <origin
      xyz="0.21565 0 8.6E-05"
      rpy="3.1416 0.57792 3.1416" />
    <parent
      link="arm_link3" />
    <child
      link="arm_link4" />
    <axis
      xyz="0 -1 0" />
    <limit
      lower="-0.8"
      upper="0.5"
      effort="100"
      velocity="3" />
  </joint>
</robot>